Traceback (most recent call last):
  File "C:\Users\Shaurya\AppData\Local\Programs\Python\Python39\lib\site-packages\urllib3\connectionpool.py", line 793, in urlopen
    response = self._make_request(
  File "C:\Users\Shaurya\AppData\Local\Programs\Python\Python39\lib\site-packages\urllib3\connectionpool.py", line 537, in _make_request
    response = conn.getresponse()
  File "C:\Users\Shaurya\AppData\Local\Programs\Python\Python39\lib\site-packages\urllib3\connection.py", line 466, in getresponse
    httplib_response = super().getresponse()
  File "C:\Users\Shaurya\AppData\Local\Programs\Python\Python39\lib\http\client.py", line 1377, in getresponse
    response.begin()
  File "C:\Users\Shaurya\AppData\Local\Programs\Python\Python39\lib\http\client.py", line 320, in begin
    version, status, reason = self._read_status()
  File "C:\Users\Shaurya\AppData\Local\Programs\Python\Python39\lib\http\client.py", line 281, in _read_status
    line = str(self.fp.readline(_MAXLINE + 1), "iso-8859-1")
  File "C:\Users\Shaurya\AppData\Local\Programs\Python\Python39\lib\socket.py", line 704, in readinto
    return self._sock.recv_into(b)
  File "C:\Users\Shaurya\AppData\Local\Programs\Python\Python39\lib\ssl.py", line 1242, in recv_into
    return self.read(nbytes, buffer)
  File "C:\Users\Shaurya\AppData\Local\Programs\Python\Python39\lib\ssl.py", line 1100, in read
    return self._sslobj.read(len, buffer)
TimeoutError: [WinError 10060] A connection attempt failed because the connected party did not properly respond after a period of time, or established connection failed because connected host has failed to respond
During handling of the above exception, another exception occurred:
Traceback (most recent call last):
  File "C:\Users\Shaurya\AppData\Local\Programs\Python\Python39\lib\site-packages\requests\adapters.py", line 486, in send
    resp = conn.urlopen(
  File "C:\Users\Shaurya\AppData\Local\Programs\Python\Python39\lib\site-packages\urllib3\connectionpool.py", line 847, in urlopen
    retries = retries.increment(
  File "C:\Users\Shaurya\AppData\Local\Programs\Python\Python39\lib\site-packages\urllib3\util\retry.py", line 470, in increment
    raise reraise(type(error), error, _stacktrace)
  File "C:\Users\Shaurya\AppData\Local\Programs\Python\Python39\lib\site-packages\urllib3\util\util.py", line 38, in reraise
    raise value.with_traceback(tb)
  File "C:\Users\Shaurya\AppData\Local\Programs\Python\Python39\lib\site-packages\urllib3\connectionpool.py", line 793, in urlopen
    response = self._make_request(
  File "C:\Users\Shaurya\AppData\Local\Programs\Python\Python39\lib\site-packages\urllib3\connectionpool.py", line 537, in _make_request
    response = conn.getresponse()
  File "C:\Users\Shaurya\AppData\Local\Programs\Python\Python39\lib\site-packages\urllib3\connection.py", line 466, in getresponse
    httplib_response = super().getresponse()
  File "C:\Users\Shaurya\AppData\Local\Programs\Python\Python39\lib\http\client.py", line 1377, in getresponse
    response.begin()
  File "C:\Users\Shaurya\AppData\Local\Programs\Python\Python39\lib\http\client.py", line 320, in begin
    version, status, reason = self._read_status()
  File "C:\Users\Shaurya\AppData\Local\Programs\Python\Python39\lib\http\client.py", line 281, in _read_status
    line = str(self.fp.readline(_MAXLINE + 1), "iso-8859-1")
  File "C:\Users\Shaurya\AppData\Local\Programs\Python\Python39\lib\socket.py", line 704, in readinto
    return self._sock.recv_into(b)
  File "C:\Users\Shaurya\AppData\Local\Programs\Python\Python39\lib\ssl.py", line 1242, in recv_into
    return self.read(nbytes, buffer)
  File "C:\Users\Shaurya\AppData\Local\Programs\Python\Python39\lib\ssl.py", line 1100, in read
    return self._sslobj.read(len, buffer)
urllib3.exceptions.ProtocolError: ('Connection aborted.', TimeoutError(10060, 'A connection attempt failed because the connected party did not properly respond after a period of time, or established connection failed because connected host has failed to respond', None, 10060, None))
During handling of the above exception, another exception occurred:
Traceback (most recent call last):
  File "c:\Shaurya\Longformer2\longformerIMDB\train.py", line 164, in <module>
    train_model(config)
  File "c:\Shaurya\Longformer2\longformerIMDB\train.py", line 92, in train_model
    train_dataloader, val_dataloader, tokenizer = get_ds(config)
  File "c:\Shaurya\Longformer2\longformerIMDB\train.py", line 50, in get_ds
    val_data_raw = load_dataset("glue", "cola", split='validation')
  File "C:\Users\Shaurya\AppData\Local\Programs\Python\Python39\lib\site-packages\datasets\load.py", line 2556, in load_dataset
    builder_instance = load_dataset_builder(
  File "C:\Users\Shaurya\AppData\Local\Programs\Python\Python39\lib\site-packages\datasets\load.py", line 2265, in load_dataset_builder
    builder_instance: DatasetBuilder = builder_cls(
  File "C:\Users\Shaurya\AppData\Local\Programs\Python\Python39\lib\site-packages\datasets\builder.py", line 371, in __init__
    self.config, self.config_id = self._create_builder_config(
  File "C:\Users\Shaurya\AppData\Local\Programs\Python\Python39\lib\site-packages\datasets\builder.py", line 620, in _create_builder_config
    builder_config._resolve_data_files(
  File "C:\Users\Shaurya\AppData\Local\Programs\Python\Python39\lib\site-packages\datasets\builder.py", line 211, in _resolve_data_files
    self.data_files = self.data_files.resolve(base_path, download_config)
  File "C:\Users\Shaurya\AppData\Local\Programs\Python\Python39\lib\site-packages\datasets\data_files.py", line 799, in resolve
    out[key] = data_files_patterns_list.resolve(base_path, download_config)
  File "C:\Users\Shaurya\AppData\Local\Programs\Python\Python39\lib\site-packages\datasets\data_files.py", line 762, in resolve
    origin_metadata = _get_origin_metadata(data_files, download_config=download_config)
  File "C:\Users\Shaurya\AppData\Local\Programs\Python\Python39\lib\site-packages\datasets\data_files.py", line 529, in _get_origin_metadata
    return thread_map(
  File "C:\Users\Shaurya\AppData\Local\Programs\Python\Python39\lib\site-packages\tqdm\contrib\concurrent.py", line 69, in thread_map
    return _executor_map(ThreadPoolExecutor, fn, *iterables, **tqdm_kwargs)
  File "C:\Users\Shaurya\AppData\Local\Programs\Python\Python39\lib\site-packages\tqdm\contrib\concurrent.py", line 51, in _executor_map
    return list(tqdm_class(ex.map(fn, *iterables, chunksize=chunksize), **kwargs))
  File "C:\Users\Shaurya\AppData\Local\Programs\Python\Python39\lib\site-packages\tqdm\std.py", line 1169, in __iter__
    for obj in iterable:
  File "C:\Users\Shaurya\AppData\Local\Programs\Python\Python39\lib\concurrent\futures\_base.py", line 609, in result_iterator
    yield fs.pop().result()
  File "C:\Users\Shaurya\AppData\Local\Programs\Python\Python39\lib\concurrent\futures\_base.py", line 446, in result
    return self.__get_result()
  File "C:\Users\Shaurya\AppData\Local\Programs\Python\Python39\lib\concurrent\futures\_base.py", line 391, in __get_result
    raise self._exception
  File "C:\Users\Shaurya\AppData\Local\Programs\Python\Python39\lib\concurrent\futures\thread.py", line 58, in run
    result = self.fn(*self.args, **self.kwargs)
  File "C:\Users\Shaurya\AppData\Local\Programs\Python\Python39\lib\site-packages\datasets\data_files.py", line 509, in _get_single_origin_metadata
    resolved_path = fs.resolve_path(data_file)
  File "C:\Users\Shaurya\AppData\Local\Programs\Python\Python39\lib\site-packages\huggingface_hub\hf_file_system.py", line 169, in resolve_path
    repo_and_revision_exist, err = self._repo_and_revision_exist(repo_type, repo_id, revision)
  File "C:\Users\Shaurya\AppData\Local\Programs\Python\Python39\lib\site-packages\huggingface_hub\hf_file_system.py", line 117, in _repo_and_revision_exist
    self._api.repo_info(repo_id, revision=revision, repo_type=repo_type)
  File "C:\Users\Shaurya\AppData\Local\Programs\Python\Python39\lib\site-packages\huggingface_hub\utils\_validators.py", line 118, in _inner_fn
    return fn(*args, **kwargs)
  File "C:\Users\Shaurya\AppData\Local\Programs\Python\Python39\lib\site-packages\huggingface_hub\hf_api.py", line 2410, in repo_info
    return method(
  File "C:\Users\Shaurya\AppData\Local\Programs\Python\Python39\lib\site-packages\huggingface_hub\utils\_validators.py", line 118, in _inner_fn
    return fn(*args, **kwargs)
  File "C:\Users\Shaurya\AppData\Local\Programs\Python\Python39\lib\site-packages\huggingface_hub\hf_api.py", line 2282, in dataset_info
    r = get_session().get(path, headers=headers, timeout=timeout, params=params)
  File "C:\Users\Shaurya\AppData\Local\Programs\Python\Python39\lib\site-packages\requests\sessions.py", line 602, in get
    return self.request("GET", url, **kwargs)
  File "C:\Users\Shaurya\AppData\Local\Programs\Python\Python39\lib\site-packages\requests\sessions.py", line 589, in request
    resp = self.send(prep, **send_kwargs)
  File "C:\Users\Shaurya\AppData\Local\Programs\Python\Python39\lib\site-packages\requests\sessions.py", line 725, in send
    history = [resp for resp in gen]
  File "C:\Users\Shaurya\AppData\Local\Programs\Python\Python39\lib\site-packages\requests\sessions.py", line 725, in <listcomp>
    history = [resp for resp in gen]
  File "C:\Users\Shaurya\AppData\Local\Programs\Python\Python39\lib\site-packages\requests\sessions.py", line 266, in resolve_redirects
    resp = self.send(
  File "C:\Users\Shaurya\AppData\Local\Programs\Python\Python39\lib\site-packages\requests\sessions.py", line 703, in send
    r = adapter.send(request, **kwargs)
  File "C:\Users\Shaurya\AppData\Local\Programs\Python\Python39\lib\site-packages\huggingface_hub\utils\_http.py", line 67, in send
    return super().send(request, *args, **kwargs)
  File "C:\Users\Shaurya\AppData\Local\Programs\Python\Python39\lib\site-packages\requests\adapters.py", line 501, in send
    raise ConnectionError(err, request=request)
requests.exceptions.ConnectionError: (ProtocolError('Connection aborted.', TimeoutError(10060, 'A connection attempt failed because the connected party did not properly respond after a period of time, or established connection failed because connected host has failed to respond', None, 10060, None)), '(Request ID: 5586b828-9f48-44a2-b946-c5778a0170f5)')